<?xml version="1.0" encoding="UTF-8"?>
<testng-results skipped="0" failed="1" ignored="0" total="1" passed="0">
  <reporter-output>
  </reporter-output>
  <suite name="Default suite" duration-ms="14578" started-at="2017-10-23T11:23:03Z" finished-at="2017-10-23T11:23:17Z">
    <groups>
    </groups>
    <test name="Default test" duration-ms="14578" started-at="2017-10-23T11:23:03Z" finished-at="2017-10-23T11:23:17Z">
      <class name="tests.Login_test_invalid_credentials">
        <test-method status="PASS" signature="beforeClass()[pri:0, instance:tests.Login_test_invalid_credentials@6a4f787b]" name="beforeClass" is-config="true" duration-ms="3409" started-at="2017-10-23T14:23:03Z" finished-at="2017-10-23T14:23:06Z">
          <reporter-output>
          </reporter-output>
        </test-method> <!-- beforeClass -->
        <test-method status="FAIL" signature="Login_test_with_valid_credentials()[pri:0, instance:tests.Login_test_invalid_credentials@6a4f787b]" name="Login_test_with_valid_credentials" duration-ms="11121" started-at="2017-10-23T14:23:06Z" finished-at="2017-10-23T14:23:17Z">
          <exception class="java.lang.AssertionError">
            <message>
              <![CDATA[expected [true] but found [false]]]>
            </message>
            <full-stacktrace>
              <![CDATA[java.lang.AssertionError: expected [true] but found [false]
	at org.testng.Assert.fail(Assert.java:93)
	at org.testng.Assert.failNotEquals(Assert.java:512)
	at org.testng.Assert.assertTrue(Assert.java:41)
	at org.testng.Assert.assertTrue(Assert.java:51)
	at pages.Login_Page.Check_welcome_text(Login_Page.java:58)
	at tests.Login_test_invalid_credentials.Login_test_with_valid_credentials(Login_test_invalid_credentials.java:54)
	at sun.reflect.NativeMethodAccessorImpl.invoke0(Native Method)
	at sun.reflect.NativeMethodAccessorImpl.invoke(Unknown Source)
	at sun.reflect.DelegatingMethodAccessorImpl.invoke(Unknown Source)
	at java.lang.reflect.Method.invoke(Unknown Source)
	at org.testng.internal.MethodInvocationHelper.invokeMethod(MethodInvocationHelper.java:108)
	at org.testng.internal.Invoker.invokeMethod(Invoker.java:669)
	at org.testng.internal.Invoker.invokeTestMethod(Invoker.java:877)
	at org.testng.internal.Invoker.invokeTestMethods(Invoker.java:1201)
	at org.testng.internal.TestMethodWorker.invokeTestMethods(TestMethodWorker.java:125)
	at org.testng.internal.TestMethodWorker.run(TestMethodWorker.java:109)
	at org.testng.TestRunner.privateRun(TestRunner.java:776)
	at org.testng.TestRunner.run(TestRunner.java:634)
	at org.testng.SuiteRunner.runTest(SuiteRunner.java:425)
	at org.testng.SuiteRunner.runSequentially(SuiteRunner.java:420)
	at org.testng.SuiteRunner.privateRun(SuiteRunner.java:385)
	at org.testng.SuiteRunner.run(SuiteRunner.java:334)
	at org.testng.SuiteRunnerWorker.runSuite(SuiteRunnerWorker.java:52)
	at org.testng.SuiteRunnerWorker.run(SuiteRunnerWorker.java:86)
	at org.testng.TestNG.runSuitesSequentially(TestNG.java:1318)
	at org.testng.TestNG.runSuitesLocally(TestNG.java:1243)
	at org.testng.TestNG.runSuites(TestNG.java:1161)
	at org.testng.TestNG.run(TestNG.java:1129)
	at org.testng.remote.AbstractRemoteTestNG.run(AbstractRemoteTestNG.java:114)
	at org.testng.remote.RemoteTestNG.initAndRun(RemoteTestNG.java:251)
	at org.testng.remote.RemoteTestNG.main(RemoteTestNG.java:77)
]]>
            </full-stacktrace>
          </exception> <!-- java.lang.AssertionError -->
          <reporter-output>
          </reporter-output>
        </test-method> <!-- Login_test_with_valid_credentials -->
        <test-method status="FAIL" signature="afterMethod(org.testng.ITestResult)[pri:0, instance:tests.Login_test_invalid_credentials@6a4f787b]" name="afterMethod" is-config="true" duration-ms="16" started-at="2017-10-23T14:23:17Z" finished-at="2017-10-23T14:23:17Z">
          <params>
            <param index="0">
              <value>
                <![CDATA[[TestResult name=Login_test_with_valid_credentials status=FAILURE method=Login_test_invalid_credentials.Login_test_with_valid_credentials()[pri:0, instance:tests.Login_test_invalid_credentials@6a4f787b] output={null}]]]>
              </value>
            </param>
          </params>
          <exception class="java.lang.ClassCastException">
            <message>
              <![CDATA[org.openqa.selenium.htmlunit.HtmlUnitDriver cannot be cast to org.openqa.selenium.TakesScreenshot]]>
            </message>
            <full-stacktrace>
              <![CDATA[java.lang.ClassCastException: org.openqa.selenium.htmlunit.HtmlUnitDriver cannot be cast to org.openqa.selenium.TakesScreenshot
	at utilities.Screenshot.takeScreenshot(Screenshot.java:16)
	at tests.Login_test_invalid_credentials.afterMethod(Login_test_invalid_credentials.java:61)
	at sun.reflect.NativeMethodAccessorImpl.invoke0(Native Method)
	at sun.reflect.NativeMethodAccessorImpl.invoke(Unknown Source)
	at sun.reflect.DelegatingMethodAccessorImpl.invoke(Unknown Source)
	at java.lang.reflect.Method.invoke(Unknown Source)
	at org.testng.internal.MethodInvocationHelper.invokeMethod(MethodInvocationHelper.java:108)
	at org.testng.internal.Invoker.invokeConfigurationMethod(Invoker.java:523)
	at org.testng.internal.Invoker.invokeConfigurations(Invoker.java:224)
	at org.testng.internal.Invoker.invokeMethod(Invoker.java:731)
	at org.testng.internal.Invoker.invokeTestMethod(Invoker.java:877)
	at org.testng.internal.Invoker.invokeTestMethods(Invoker.java:1201)
	at org.testng.internal.TestMethodWorker.invokeTestMethods(TestMethodWorker.java:125)
	at org.testng.internal.TestMethodWorker.run(TestMethodWorker.java:109)
	at org.testng.TestRunner.privateRun(TestRunner.java:776)
	at org.testng.TestRunner.run(TestRunner.java:634)
	at org.testng.SuiteRunner.runTest(SuiteRunner.java:425)
	at org.testng.SuiteRunner.runSequentially(SuiteRunner.java:420)
	at org.testng.SuiteRunner.privateRun(SuiteRunner.java:385)
	at org.testng.SuiteRunner.run(SuiteRunner.java:334)
	at org.testng.SuiteRunnerWorker.runSuite(SuiteRunnerWorker.java:52)
	at org.testng.SuiteRunnerWorker.run(SuiteRunnerWorker.java:86)
	at org.testng.TestNG.runSuitesSequentially(TestNG.java:1318)
	at org.testng.TestNG.runSuitesLocally(TestNG.java:1243)
	at org.testng.TestNG.runSuites(TestNG.java:1161)
	at org.testng.TestNG.run(TestNG.java:1129)
	at org.testng.remote.AbstractRemoteTestNG.run(AbstractRemoteTestNG.java:114)
	at org.testng.remote.RemoteTestNG.initAndRun(RemoteTestNG.java:251)
	at org.testng.remote.RemoteTestNG.main(RemoteTestNG.java:77)
]]>
            </full-stacktrace>
          </exception> <!-- java.lang.ClassCastException -->
          <reporter-output>
          </reporter-output>
        </test-method> <!-- afterMethod -->
        <test-method status="SKIP" signature="afterClass()[pri:0, instance:tests.Login_test_invalid_credentials@6a4f787b]" name="afterClass" is-config="true" duration-ms="0" started-at="2017-10-23T14:23:17Z" finished-at="2017-10-23T14:23:17Z">
          <reporter-output>
          </reporter-output>
        </test-method> <!-- afterClass -->
      </class> <!-- tests.Login_test_invalid_credentials -->
    </test> <!-- Default test -->
  </suite> <!-- Default suite -->
</testng-results>
